Workbook

Sheet Balance Sheet
A1: TATA STEEL LIMITED — Consolidated Balance Sheet (₹ in Crores)
A2: Particulars | B2: FY '21 | C2: FY '22 | D2: FY '23 | E2: FY '24 | F2: FY '25 | G2: Forecast FY'26 | H2: Forecast FY'27
A3: EQUITY AND LIABILITIES
A4: Shareholders' Funds
A5: Equity Share Capital | B5: 1197.61 | C5: 1221.21 | D5: 1221.24 | E5: 1247.44 | F5: 1247.44 | G5: 1247.44 | H5: 1247.44
A6: Reserves and Surplus | B6: 72262.38 | C6: 113221.83 | D6: 101860.86 | E6: 90788.32 | F6: 89922.19 | G6: =F6+'P & L Statement'!G23-'P & L Statement'!G28 -> 100648.76 | H6: =G6+'P & L Statement'!H23-'P & L Statement'!H28 -> 111179.13
A7: Total Shareholders' Funds | B7: =SUM(B5:B6) -> 73459.99 | C7: =SUM(C5:C6) -> 114443.04 | D7: =SUM(D5:D6) -> 103082.1 | E7: =SUM(E5:E6) -> 92035.76 | F7: =SUM(F5:F6) -> 91169.63 | G7: =SUM(G5:G6) -> 101896.2 | H7: =SUM(H5:H6) -> 112426.57
A8: Minority Interest | B8: 3269.68 | C8: 2655.42 | D8: 2093.11 | E8: 396.98 | F8: 183.15 | G8: 183.15 | H8: 183.15
A9: Non-Current Liabilities
A10: Long Term Borrowings | B10: 65698.01 | C10: 44764.07 | D10: 51446.33 | E10: 51576.73 | F10: 68551.81 | G10: 68551.81 | H10: 68551.81
A11: Deferred Tax Liabilities (Net) | B11: 9241.42 | C11: 12325.78 | D11: 14115.64 | E11: 12992.34 | F11: 14430.15 | G11: ='P & L Statement'!$G$4*(F11/'P & L Statement'!F4) -> 15687.073 | H11: ='P & L Statement'!H4*(G11/'P & L Statement'!G4) -> 17053.479
A12: Other Long Term Liabilities | B12: 17480.28 | C12: 15843.31 | D12: 15213.59 | E12: 12594.18 | F12: 13160.01 | G12: =F12*(1+'Common size BS'!G32) -> 13878.338 | H12: =G12*(1+'Common size BS'!H32) -> 14589.108
A13: Long Term Provisions | B13: 4691.92 | C13: 4825.98 | D13: 4775.84 | E13: 5424.03 | F13: 5806.5 | G13: =F13*(1+'Common size BS'!G33) -> 5914.8281 | H13: =G13*(1+'Common size BS'!H33) -> 6024.5654
A14: Total Non-Current Liabilities | B14: =SUM(B10:B13) -> 97111.63 | C14: =SUM(C10:C13) -> 77759.14 | D14: =SUM(D10:D13) -> 85551.4 | E14: =SUM(E10:E13) -> 82587.28 | F14: =SUM(F10:F13) -> 101948.47 | G14: =SUM(G10:G13) -> 104032.05 | H14: =SUM(H10:H13) -> 106218.96
A15: Current Liabilities
A16: Short Term Borrowings | B16: 14968.97 | C16: 24064.61 | D16: 26571.37 | E16: 29997.19 | F16: 20412 | G16: 20412 | H16: 20412
A17: Trade Payables | B17: 25967.49 | C17: 36764.87 | D17: 37832.54 | E17: 35434.66 | F17: 29314.38 | G17: ='P & L Statement'!$G$4*('Balance Sheet'!F17/'P & L Statement'!$F$4) -> 31867.778 | H17: ='P & L Statement'!$H$4*('Balance Sheet'!G17/'P & L Statement'!$G$4) -> 34643.588
A18: Other Current Liabilities | B18: 25205.35 | C18: 26990.03 | D18: 29008.49 | E18: 29192.55 | F18: 32478.88 | G18: ='P & L Statement'!$G$4*('Balance Sheet'!F18/'P & L Statement'!$F$4) -> 35307.919 | H18: ='P & L Statement'!$H$4*('Balance Sheet'!G18/'P & L Statement'!$G$4) -> 38383.378
A19: Short Term Provisions | B19: 4725.32 | C19: 2768.49 | D19: 3882.73 | E19: 3779.08 | F19: 3888.29 | G19: =F19*(1+'Common size BS'!G39) -> 3942.9031 | H19: =G19*(1+'Common size BS'!H39) -> 3994.1319
A20: Total Current Liabilities | B20: =SUM(B16:B19) -> 70867.13 | C20: =SUM(C16:C19) -> 90588 | D20: =SUM(D16:D19) -> 97295.13 | E20: =SUM(E16:E19) -> 98403.48 | F20: =SUM(F16:F19) -> 86093.55 | G20: =SUM(G16:G19) -> 91530.601 | H20: =SUM(H16:H19) -> 97433.098
A21: TOTAL EQUITY AND LIABILITIES | B21: =SUM(B7,B14,B20,B8) -> 244708.43 | C21: =SUM(C7,C14,C20,C8) -> 285445.6 | D21: =SUM(D7,D14,D20,D8) -> 288021.74 | E21: =SUM(E7,E14,E20,E8) -> 273423.5 | F21: =SUM(F7,F14,F20,F8) -> 279394.8 | G21: =SUM(G7,G14,G20,G8) -> 297642 | H21: =SUM(H7,H14,H20,H8) -> 316261.78
A22: ASSETS
A23: Non-Current Assets
A24: Tangible Assets | B24: 128454.45 | C24: 124504.16 | D24: 127919.26 | E24: 131124.03 | F24: 133303.12 | G24: ='P & L Statement'!G4*('Balance Sheet'!F24/'P & L Statement'!F4) -> 144914.35 | H24: ='Balance Sheet'!G24*(1+'Common size BS'!H6) -> 211846.38
A25: Intangible Assets | B25: 2976.04 | C25: 4472.47 | D25: 13100.55 | E25: 11945.05 | F25: 11652.41 | G25: ='Balance Sheet'!F25*(1+'Common size BS'!G7) -> 12022.275 | H25: ='Balance Sheet'!G25*(1+'Common size BS'!H7) -> 12450.959
A26: Intangible Assets Under Development | B26: 878.66 | C26: 817.93 | D26: 905.12 | E26: 985.34 | F26: 1020.47 | G26: ='Balance Sheet'!F26*(1+'Common size BS'!G8) -> 1023.91 | H26: ='Balance Sheet'!G26*(1+'Common size BS'!H8) -> 1027.3165
A27: Capital Work-In-Progress | B27: 18128.74 | C27: 21227.62 | D27: 30307.9 | E27: 33370.19 | F27: 40601.88 | G27: ='Balance Sheet'!F27*(1+'Common size BS'!G9) -> 44832.954 | H27: ='Balance Sheet'!G27*(1+'Common size BS'!H9) -> 49775.068
A28: Total Fixed Assets | B28: =SUM(B24:B27) -> 150437.89 | C28: =SUM(C24:C27) -> 151022.18 | D28: =SUM(D24:D27) -> 172232.83 | E28: =SUM(E24:E27) -> 177424.61 | F28: =SUM(F24:F27) -> 186577.88 | G28: =SUM(G24:G27) -> 202793.49 | H28: =SUM(H24:H27) -> 275099.73
A29: Non-Current Investments | B29: 3463.04 | C29: 4615.43 | D29: 4780.25 | E29: 5526.35 | F29: 5751.46 | G29: =F29*(1+'Common size BS'!G11) -> 5852.3577 | H29: =G29*(1+'Common size BS'!H11) -> 5958.9948
A30: Deferred Tax Assets (Net) | B30: 1578.02 | C30: 3023.93 | D30: 2625.96 | E30: 4111.08 | F30: 3936.22 | G30: =F30*(1+'Common size BS'!G12) -> 3979.7416 | H30: =G30*(1+'Common size BS'!H12) -> 4027.4122
A31: Long Term Loans & Advances | B31: 91.93 | C31: 1282.44 | D31: 64.74 | E31: 73.14 | F31: 114.66 | G31: =F31*(1+'Common size BS'!G13) -> 114.79234 | H31: =G31*(1+'Common size BS'!H13) -> 114.94271
A32: Other Non-Current Assets | B32: 28925.65 | C32: 32945.01 | D32: 21652.42 | E32: 15740.08 | F32: 14623.04 | G32: =F32*(1+'Common size BS'!G14) -> 15847.579 | H32: =G32*(1+'Common size BS'!H14) -> 17065.426
A33: Total Non-Current Assets | B33: =SUM(B28:B32) -> 184496.53 | C33: =SUM(C28:C32) -> 192888.99 | D33: =SUM(D28:D32) -> 201356.2 | E33: =SUM(E28:E32) -> 202875.26 | F33: =SUM(F28:F32) -> 211003.26 | G33: =SUM(G28:G32) -> 228587.96 | H33: =SUM(H28:H32) -> 302266.5
A34: Current Assets
A35: Current Investments | B35: 7218.89 | C35: 8524.42 | D35: 3630.06 | E35: 731.22 | F35: 442.65 | G35: =F35*(1+'Common size BS'!G17) -> 449.39825 | H35: =G35*(1+'Common size BS'!H17) -> 454.96816
A36: Inventories | B36: 33276.38 | C36: 48824.39 | D36: 54415.33 | E36: 49157.51 | F36: 44589.94 | G36: ='P & L Statement'!G4*('Balance Sheet'!F36/'P & L Statement'!F4) -> 48473.9 | H36: ='P & L Statement'!H4*('Balance Sheet'!G36/'P & L Statement'!G4) -> 52696.169
A37: Trade Receivables | B37: 9539.84 | C37: 12246.43 | D37: 8257.24 | E37: 6263.53 | F37: 5260.06 | G37: ='P & L Statement'!G4*('Balance Sheet'!F37/'P & L Statement'!F4) -> 5718.232 | H37: ='P & L Statement'!H4*('Balance Sheet'!G37/'P & L Statement'!G4) -> 6216.3127
A38: Cash and Cash Equivalents | B38: 5782.18 | C38: 15898.93 | D38: 13357.26 | E38: 8677.72 | F38: 11646.98 | G38: =G21-(SUM(G33,G35:G37,G39:G40)) -> 7817.5337 | H38: =H21-(SUM(H33,H35:H37,H39:H40)) -> -52118.993
A39: Short Term Loans & Advances | B39: 5.59 | C39: 5.84 | D39: 1.84 | E39: 1.6 | F39: 4.98 | G39: =F39*(1+'Common size BS'!G21) -> 4.9800731 | H39: =G39*(1+'Common size BS'!H21) -> 4.980138
A40: Other Current Assets | B40: 4389.02 | C40: 7056.6 | D40: 7003.81 | E40: 5716.66 | F40: 6446.93 | G40: =F40*(1+'Common size BS'!G22) -> 6589.9956 | H40: =G40*(1+'Common size BS'!H22) -> 6741.8447
...

Sheet P & L Statement
A1: TATA STEEL LIMITED — Consolidated Profit & Loss Statement (₹ in Crores)
A2: Particulars | B2: FY '21 | C2: FY '22 | D2: FY '23 | E2: FY '24 | F2: FY '25 | G2: Forecast FY'26 | H2: Forecast FY'27
A3: INCOME | F3: Growth rate- | G3: =(F4/B4)^(1/4)-1 -> 0.087103956
A4: Sales Turnover | B4: 156477.4 | C4: 243959.17 | D4: 243352.69 | E4: 229170.78 | F4: 218542.51 | G4: =F4*(1+G3) -> 237578.43 | H4: =G4*(1+G3) -> 258272.45
A5: Non-operating income | B5: -7774.82 | C5: 1017.22 | D5: -8830.86 | E5: -10676.8 | F5: 635.4 | G5: =$G$4*('Common size pl'!G4) -> -5962.5826 | H5: =$H$4*'Common size pl'!H4 -> -5211.8039
A6: Stock Adjustments | B6: -1516.77 | C6: 7597.87 | D6: 3358.89 | E6: -4409.35 | F6: 96.65 | G6: =$G$4*('Common size pl'!G5) -> 781.87797 | H6: =$H$4*'Common size pl'!H5 -> 1520.6775
A7: Total Income | B7: =SUM(B4:B6) -> 147185.81 | C7: =SUM(C4:C6) -> 252574.26 | D7: =SUM(D4:D6) -> 237880.72 | E7: =SUM(E4:E6) -> 214084.63 | F7: =SUM(F4:F6) -> 219274.56 | G7: =SUM(G4:G6) -> 232397.72 | H7: =SUM(H4:H6) -> 254581.32
A8: EXPENDITURE
A9: Raw Materials | B9: 65969.12 | C9: 107035.51 | D9: 138072.27 | E9: 116247.44 | F9: 106076.18 | G9: =$G$4*'Common size pl'!G8 -> 115004.12 | H9: =$H$4*'Common size pl'!H8 -> 128248.76
A10: Power & Fuel Cost | B10: 5708.42 | C10: 8028.29 | D10: 9526.91 | E10: 10071.85 | F10: 13124.85 | G10: =$G$4*'Common size pl'!G9 -> 10099.13 | H10: =$H$4*'Common size pl'!H9 -> 11290.168
A11: Employee Cost | B11: 19908.81 | C11: 23264.1 | D11: 22419.32 | E11: 24509.58 | F11: 24888.99 | G11: =$G$4*'Common size pl'!G10 -> 25447.213 | H11: =$H$4*'Common size pl'!H10 -> 26624.455
A12: Miscellaneous Expenses | B12: 32870.02 | C12: 49739.19 | D12: 44392.92 | E12: 51626.66 | F12: 49250.69 | G12: =$G$4*'Common size pl'!G11 -> 49749.09 | H12: =$H$4*'Common size pl'!H11 -> 54048.252
A13: COGS | B13: =SUM(B9:B12) -> 124456.37 | C13: =SUM(C9:C12) -> 188067.09 | D13: =SUM(D9:D12) -> 214411.42 | E13: =SUM(E9:E12) -> 202455.53 | F13: =SUM(F9:F12) -> 193340.71 | G13: =SUM(G9:G12) -> 200299.55 | H13: =SUM(H9:H12) -> 220211.64
A14: PROFITABILITY
A15: Operating Profit (EBITDA) | B15: =B7-B13 -> 22729.44 | C15: =C7-C13 -> 64507.17 | D15: =D7-D13 -> 23469.3 | E15: =E7-E13 -> 11629.1 | F15: =F7-F13 -> 25933.85 | G15: =G7-G13 -> 32098.175 | H15: =H7-H13 -> 34369.686
A16: Less: Interest | B16: 7606.71 | C16: 5462.2 | D16: 6298.7 | E16: 7507.57 | F16: 7340.95 | G16: 7340.95 | H16: 7340.95
A17: PBDT | B17: =B15-B16 -> 15122.73 | C17: =C15-C16 -> 59044.97 | D17: =D15-D16 -> 17170.6 | E17: =E15-E16 -> 4121.53 | F17: =F15-F16 -> 18592.9 | G17: =G15-G16 -> 24757.225 | H17: =H15-H16 -> 27028.736
A18: Less: Depreciation | B18: 9233.64 | C18: 9100.87 | D18: 9335.2 | E18: 9882.16 | F18: 10421.33 | G18: =G4*'Common size pl'!G17 -> 10713.935 | H18: =H4*'Common size pl'!H17 -> 10928.492
A19: Profit Before Tax (PBT) | B19: =B17-B18 -> 5889.09 | C19: =C17-C18 -> 49944.1 | D19: =D17-D18 -> 7835.4 | E19: =E17-E18 -> -5760.63 | F19: =F17-F18 -> 8171.57 | G19: =G17-G18 -> 14043.29 | H19: =H17-H18 -> 16100.244
A20: Tax (incl. Deferred Tax) | B20: 5653.9 | C20: 8477.55 | D20: 10159.77 | E20: 3762.57 | F20: 5239.09 | G20: =G19*0.3 -> 4212.9869 | H20: =H19*0.3 -> 4830.0732
A21: PAT | B21: =B19-B20 -> 235.19 | C21: =C19-C20 -> 41466.55 | D21: =D19-D20 -> -2324.37 | E21: =E19-E20 -> -9523.2 | F21: =F19-F20 -> 2932.48 | G21: =G19-G20 -> 9830.3027 | H21: =H19-H20 -> 11270.171
A22: Less: Non-Controlling Interest | B22: -6927.69 | C22: 1961.78 | D22: -10666.65 | E22: -5143.74 | F22: -297.22 | G22: =G4*'Common size pl'!G21 -> -4935.3799 | H22: =H4*'Common size pl'!H21 -> -4151.4372
A23: Reported Net Profit | B23: =B21-B22 -> 7162.88 | C23: =C21-C22 -> 39504.77 | D23: =D21-D22 -> 8342.28 | E23: =E21-E22 -> -4379.46 | F23: =F21-F22 -> 3229.7 | G23: =G21-G22 -> 14765.683 | H23: =H21-H22 -> 15421.608
A24: PER SHARE DATA
A25: Shares in Issue (Lakhs) | B25: 12029.45 | C25: 12211.77 | D25: 12209.85 | E25: 12105.05 | F25: 124718.48 | G25: =$G$4*'Common size pl'!G24 -> 38041.566 | H25: =$H$4*'Common size pl'!H24 -> 45655.143
A26: Earnings Per Share (₹) | B26: =B23/B25*100 -> 59.544534 | C26: =C23/C25*100 -> 323.49749 | D26: =D23/D25*100 -> 68.324181 | E26: =E23/E25*100 -> -36.178785 | F26: =F23/F25*100 -> 2.5895922 | G26: =G23/G25*100 -> 38.814602 | H26: =H23/H25*100 -> 33.778468
A27: Book Value Per Share (₹) | B27: 610.67 | C27: 937.15 | D27: 84.43 | E27: 73.79 | F27: 73.1 | G27: 73.1 | H27: 73.1
A28: Equity Dividend (₹ Cr) | B28: 1144.75 | C28: 3004.16 | D28: 6227.15 | E28: 4409.79 | F28: 4489.87 | G28: =$G$4*'Common size pl'!G27 -> 4039.1145 | H28: =$H$4*'Common size pl'!H27 -> 4891.2333
A29: OTHER METRICS
A30: Share of P/L of Associates | B30: -327.34 | C30: -649.16 | D30: -418.12 | E30: 57.98 | F30: -190.81 | G30: -190.81 | H30: -190.81
A31: Net P/L after MI & Associates | B31: 9232.95 | C31: 41883.38 | D31: 7962.09 | E31: 2904.47 | F31: 4028.42 | G31: =$G$4*'Common size pl'!G30 -> 13993.949 | H31: =$H$4*'Common size pl'!H30 -> 15207.579
A32: Total Value Addition | B32: 58487.25 | C32: 81031.58 | D32: 76339.15 | E32: 86208.09 | F32: 87264.53 | G32: =$G$4*'Common size pl'!G31 -> 85295.433 | H32: =$H$4*'Common size pl'!H31 -> 91962.876

Sheet Cash Flow Statement
A1: TATA STEEL LIMITED — Consolidated Cash Flow Statement (₹ in Crores)
A2: Particulars | B2: FY '21 | C2: FY '22 | D2: FY '23 | E2: FY '24 | F2: FY '25
A3: A. OPERATING ACTIVITIES
A4: Net Earnings | B4: ='P & L Statement'!B21 -> 235.19 | C4: ='P & L Statement'!C21 -> 41466.55 | D4: ='P & L Statement'!D21 -> -2324.37 | E4: ='P & L Statement'!E21 -> -9523.2 | F4: ='P & L Statement'!F21 -> 2932.48
A5: Add: Depreciation & Amortisation | B5: ='P & L Statement'!B18 -> 9233.64 | C5: ='P & L Statement'!C18 -> 9100.87 | D5: ='P & L Statement'!D18 -> 9335.2 | E5: ='P & L Statement'!E18 -> 9882.16 | F5: ='P & L Statement'!F18 -> 10421.33
A6: Less: Other Income | B6: ='P & L Statement'!B5 -> -7774.82 | C6: ='P & L Statement'!C5 -> 1017.22 | D6: ='P & L Statement'!D5 -> -8830.86 | E6: ='P & L Statement'!E5 -> -10676.8 | F6: ='P & L Statement'!F5 -> 635.4
A7: Change in Working Capital | B7: 0 | C7: =('Balance Sheet'!C41-'Balance Sheet'!C20)-('Balance Sheet'!B41-'Balance Sheet'!B20) -> 12623.84 | D7: =('Balance Sheet'!D41-'Balance Sheet'!D20)-('Balance Sheet'!C41-'Balance Sheet'!C20) -> -12598.2 | E7: =('Balance Sheet'!E41-'Balance Sheet'!E20)-('Balance Sheet'!D41-'Balance Sheet'!D20) -> -17225.65 | F7: =('Balance Sheet'!F41-'Balance Sheet'!F20)-('Balance Sheet'!E41-'Balance Sheet'!E20) -> 10153.23
A8: Cash from Operations | B8: =SUM(B4:B7) -> 1694.01 | C8: =SUM(C4:C7) -> 64208.48 | D8: =SUM(D4:D7) -> -14418.23 | E8: =SUM(E4:E7) -> -27543.49 | F8: =SUM(F4:F7) -> 24142.44
A9: B. INVESTING ACTIVITIES
A10: Change in Tangible Assets | B10: 0 | C10: ='Balance Sheet'!B24-'Balance Sheet'!C24 -> 3950.29 | D10: ='Balance Sheet'!C24-'Balance Sheet'!D24 -> -3415.1 | E10: ='Balance Sheet'!D24-'Balance Sheet'!E24 -> -3204.77 | F10: ='Balance Sheet'!E24-'Balance Sheet'!F24 -> -2179.09
A11: Change in Intangible Assets | B11: 0 | C11: ='Balance Sheet'!B25-'Balance Sheet'!C25 -> -1496.43 | D11: ='Balance Sheet'!C25-'Balance Sheet'!D25 -> -8628.08 | E11: ='Balance Sheet'!D25-'Balance Sheet'!E25 -> 1155.5 | F11: ='Balance Sheet'!E25-'Balance Sheet'!F25 -> 292.64
A12: Change in CWIP | B12: 0 | C12: ='Balance Sheet'!B27-'Balance Sheet'!C27 -> -3098.88 | D12: ='Balance Sheet'!C27-'Balance Sheet'!D27 -> -9080.28 | E12: ='Balance Sheet'!D27-'Balance Sheet'!E27 -> -3062.29 | F12: ='Balance Sheet'!E27-'Balance Sheet'!F27 -> -7231.69
A13: Change in Investments | B13: 0 | C13: ='Balance Sheet'!B29-'Balance Sheet'!C29 -> -1152.39 | D13: ='Balance Sheet'!C29-'Balance Sheet'!D29 -> -164.82 | E13: ='Balance Sheet'!D29-'Balance Sheet'!E29 -> -746.1 | F13: ='Balance Sheet'!E29-'Balance Sheet'!F29 -> -225.11
A14: Change in Other NCA | B14: 0 | C14: ='Balance Sheet'!B32-'Balance Sheet'!C32 -> -4019.36 | D14: ='Balance Sheet'!C32-'Balance Sheet'!D32 -> 11292.59 | E14: ='Balance Sheet'!D32-'Balance Sheet'!E32 -> 5912.34 | F14: ='Balance Sheet'!E32-'Balance Sheet'!F32 -> 1117.04
A15: Change in Current Investments | B15: 0 | C15: ='Balance Sheet'!B35-'Balance Sheet'!C35 -> -1305.53 | D15: ='Balance Sheet'!C35-'Balance Sheet'!D35 -> 4894.36 | E15: ='Balance Sheet'!D35-'Balance Sheet'!E35 -> 2898.84 | F15: ='Balance Sheet'!E35-'Balance Sheet'!F35 -> 288.57
A16: Cash from Investing | B16: =SUM(B10:B15) -> 0 | C16: =SUM(C10:C15) -> -7122.3 | D16: =SUM(D10:D15) -> -5101.33 | E16: =SUM(E10:E15) -> 2953.52 | F16: =SUM(F10:F15) -> -7937.64
A17: C. FINANCING ACTIVITIES
A18: LT Debt Change | B18: 0 | C18: ='Balance Sheet'!C10-'Balance Sheet'!B10 -> -20933.94 | D18: ='Balance Sheet'!D10-'Balance Sheet'!C10 -> 6682.26 | E18: ='Balance Sheet'!E10-'Balance Sheet'!D10 -> 130.4 | F18: ='Balance Sheet'!F10-'Balance Sheet'!E10 -> 16975.08
A19: ST Debt Change | B19: 0 | C19: ='Balance Sheet'!C16-'Balance Sheet'!B16 -> 9095.64 | D19: ='Balance Sheet'!D16-'Balance Sheet'!C16 -> 2506.76 | E19: ='Balance Sheet'!E16-'Balance Sheet'!D16 -> 3425.82 | F19: ='Balance Sheet'!F16-'Balance Sheet'!E16 -> -9585.19
A20: Equity Issued | B20: 0 | C20: ='Balance Sheet'!C5-'Balance Sheet'!B5 -> 23.6 | D20: ='Balance Sheet'!D5-'Balance Sheet'!C5 -> 0.03 | E20: ='Balance Sheet'!E5-'Balance Sheet'!D5 -> 26.2 | F20: ='Balance Sheet'!F5-'Balance Sheet'!E5 -> 0
A21: Minority Interest Change | B21: 0 | C21: ='Balance Sheet'!C8-'Balance Sheet'!B8 -> -614.26 | D21: ='Balance Sheet'!D8-'Balance Sheet'!C8 -> -562.31 | E21: ='Balance Sheet'!E8-'Balance Sheet'!D8 -> -1696.13 | F21: ='Balance Sheet'!F8-'Balance Sheet'!E8 -> -213.83
A22: Dividends Paid | B22: 0 | C22: =-'P & L Statement'!C28 -> -3004.16 | D22: =-'P & L Statement'!D28 -> -6227.15 | E22: =-'P & L Statement'!E28 -> -4409.79 | F22: =-'P & L Statement'!F28 -> -4489.87
A23: Cash from Financing | B23: =SUM(B18:B22) -> 0 | C23: =SUM(C18:C22) -> -15433.12 | D23: =SUM(D18:D22) -> 2399.59 | E23: =SUM(E18:E22) -> -2523.5 | F23: =SUM(F18:F22) -> 2686.19
A24: NET CHANGE IN CASH
A25: Net Increase / (Decrease) in Cash | B25: 8621.7 | C25: =SUM(C8,C16,C23) -> 41653.06 | D25: =SUM(D8,D16,D23) -> -17119.97 | E25: =SUM(E8,E16,E23) -> -27113.47 | F25: =SUM(F8,F16,F23) -> 18890.99
A26: Opening Cash Balance | B26: 0 | C26: ='Balance Sheet'!B38 -> 5782.18 | D26: ='Balance Sheet'!C38 -> 15898.93 | E26: ='Balance Sheet'!D38 -> 13357.26 | F26: ='Balance Sheet'!E38 -> 8677.72
A27: Closing Cash Balance | B27: =B25+B26 -> 8621.7 | C27: =C25+C26 -> 47435.24 | D27: =D25+D26 -> -1221.04 | E27: =E25+E26 -> -13756.21 | F27: =F25+F26 -> 27568.71

Sheet Common size BS
A1: TATA STEEL LIMITED — CommanSize Balance Sheet (₹ in Crores)
A2: Particulars | B2: FY '21 | C2: FY '22 | D2: FY '23 | E2: FY '24 | F2: FY '25 | G2: Forecast FY'26 | H2: Forecast FY'27
A4: TOTAL ASSETS | B4: {='Balance Sheet'!B42:F42} -> 244708.43 | C4: 285445.6 | D4: 288021.74 | E4: 273423.5 | F4: 279394.8 | G4: ='Balance Sheet'!G42 -> 297642 | H4: ='Balance Sheet'!H42 -> 316261.78
A5: {='Balance Sheet'!A23:A41} -> Non-Current Assets
A6: Tangible Assets | B6: ='Balance Sheet'!B24/'Common size BS'!$B$4 -> 0.52492859 | C6: ='Balance Sheet'!C24/'Common size BS'!$C$4 -> 0.43617474 | D6: ='Balance Sheet'!D24/'Common size BS'!$D$4 -> 0.44413057 | E6: ='Balance Sheet'!E24/'Common size BS'!$E$4 -> 0.47956386 | F6: ='Balance Sheet'!F24/'Common size BS'!$F$4 -> 0.47711382 | G6: =AVERAGE(B6:F6) -> 0.47238232 | H6: =AVERAGE(C6:G6) -> 0.46187306
A7: Intangible Assets | B7: ='Balance Sheet'!B25/'Common size BS'!$B$4 -> 0.012161575 | C7: ='Balance Sheet'!C25/'Common size BS'!$C$4 -> 0.01566838 | D7: ='Balance Sheet'!D25/'Common size BS'!$D$4 -> 0.045484587 | E7: ='Balance Sheet'!E25/'Common size BS'!$E$4 -> 0.043686991 | F7: ='Balance Sheet'!F25/'Common size BS'!$F$4 -> 0.041705894 | G7: =AVERAGE(B7:F7) -> 0.031741486 | H7: =AVERAGE(C7:G7) -> 0.035657468
A8: Intangible Assets Under Development | B8: ='Balance Sheet'!B26/'Common size BS'!$B$4 -> 0.0035906405 | C8: ='Balance Sheet'!C26/'Common size BS'!$C$4 -> 0.0028654497 | D8: ='Balance Sheet'!D26/'Common size BS'!$D$4 -> 0.0031425406 | E8: ='Balance Sheet'!E26/'Common size BS'!$E$4 -> 0.0036037137 | F8: ='Balance Sheet'!F26/'Common size BS'!$F$4 -> 0.0036524302 | G8: =AVERAGE(B8:F8) -> 0.0033709549 | H8: =AVERAGE(C8:G8) -> 0.0033270178
A9: Capital Work-In-Progress | B9: ='Balance Sheet'!B27/'Common size BS'!$B$4 -> 0.074083022 | C9: ='Balance Sheet'!C27/'Common size BS'!$C$4 -> 0.074366604 | D9: ='Balance Sheet'!D27/'Common size BS'!$D$4 -> 0.10522782 | E9: ='Balance Sheet'!E27/'Common size BS'!$E$4 -> 0.1220458 | F9: ='Balance Sheet'!F27/'Common size BS'!$F$4 -> 0.14532081 | G9: =AVERAGE(B9:F9) -> 0.10420881 | H9: =AVERAGE(C9:G9) -> 0.11023397
A10: Total Fixed Assets | B10: ='Balance Sheet'!B28/'Common size BS'!$B$4 -> 0.61476382 | C10: ='Balance Sheet'!C28/'Common size BS'!$C$4 -> 0.52907517 | D10: ='Balance Sheet'!D28/'Common size BS'!$D$4 -> 0.59798552 | E10: ='Balance Sheet'!E28/'Common size BS'!$E$4 -> 0.64890037 | F10: ='Balance Sheet'!F28/'Common size BS'!$F$4 -> 0.66779296 | G10: =AVERAGE(B10:F10) -> 0.61170357 | H10: =AVERAGE(C10:G10) -> 0.61109152
A11: Non-Current Investments | B11: ='Balance Sheet'!B29/'Common size BS'!$B$4 -> 0.014151699 | C11: ='Balance Sheet'!C29/'Common size BS'!$C$4 -> 0.016169211 | D11: ='Balance Sheet'!D29/'Common size BS'!$D$4 -> 0.016596837 | E11: ='Balance Sheet'!E29/'Common size BS'!$E$4 -> 0.020211686 | F11: ='Balance Sheet'!F29/'Common size BS'!$F$4 -> 0.020585422 | G11: =AVERAGE(B11:F11) -> 0.017542971 | H11: =AVERAGE(C11:G11) -> 0.018221226
A12: Deferred Tax Assets (Net) | B12: ='Balance Sheet'!B30/'Common size BS'!$B$4 -> 0.0064485723 | C12: ='Balance Sheet'!C30/'Common size BS'!$C$4 -> 0.010593717 | D12: ='Balance Sheet'!D30/'Common size BS'!$D$4 -> 0.0091172284 | E12: ='Balance Sheet'!E30/'Common size BS'!$E$4 -> 0.015035577 | F12: ='Balance Sheet'!F30/'Common size BS'!$F$4 -> 0.01408838 | G12: =AVERAGE(B12:F12) -> 0.011056695 | H12: =AVERAGE(C12:G12) -> 0.011978319
A13: Long Term Loans & Advances | B13: ='Balance Sheet'!B31/'Common size BS'!$B$4 -> 0.00037567157 | C13: ='Balance Sheet'!C31/'Common size BS'!$C$4 -> 0.004492765 | D13: ='Balance Sheet'!D31/'Common size BS'!$D$4 -> 0.0002247747 | E13: ='Balance Sheet'!E31/'Common size BS'!$E$4 -> 0.00026749712 | F13: ='Balance Sheet'!F31/'Common size BS'!$F$4 -> 0.00041038702 | G13: =AVERAGE(B13:F13) -> 0.0011542191 | H13: =AVERAGE(C13:G13) -> 0.0013099286
A14: Other Non-Current Assets | B14: ='Balance Sheet'!B32/'Common size BS'!$B$4 -> 0.11820455 | C14: ='Balance Sheet'!C32/'Common size BS'!$C$4 -> 0.11541607 | D14: ='Balance Sheet'!D32/'Common size BS'!$D$4 -> 0.075176339 | E14: ='Balance Sheet'!E32/'Common size BS'!$E$4 -> 0.057566669 | F14: ='Balance Sheet'!F32/'Common size BS'!$F$4 -> 0.052338268 | G14: =AVERAGE(B14:F14) -> 0.08374038 | H14: =AVERAGE(C14:G14) -> 0.076847546
A15: Total Non-Current Assets | B15: ='Balance Sheet'!B33/'Common size BS'!$B$4 -> 0.75394432 | C15: ='Balance Sheet'!C33/'Common size BS'!$C$4 -> 0.67574694 | D15: ='Balance Sheet'!D33/'Common size BS'!$D$4 -> 0.6991007 | E15: ='Balance Sheet'!E33/'Common size BS'!$E$4 -> 0.7419818 | F15: ='Balance Sheet'!F33/'Common size BS'!$F$4 -> 0.75521542 | G15: =AVERAGE(B15:F15) -> 0.72519783 | H15: =AVERAGE(C15:G15) -> 0.71944854
A16: Current Assets
A17: Current Investments | B17: ='Balance Sheet'!B35/'Common size BS'!$B$4 -> 0.029499965 | C17: ='Balance Sheet'!C35/'Common size BS'!$C$4 -> 0.029863554 | D17: ='Balance Sheet'!D35/'Common size BS'!$D$4 -> 0.012603424 | E17: ='Balance Sheet'!E35/'Common size BS'!$E$4 -> 0.0026743129 | F17: ='Balance Sheet'!F35/'Common size BS'!$F$4 -> 0.0015843172 | G17: =AVERAGE(B17:F17) -> 0.015245114 | H17: =AVERAGE(C17:G17) -> 0.012394144
A18: Inventories | B18: ='Balance Sheet'!B36/'Common size BS'!$B$4 -> 0.13598379 | C18: ='Balance Sheet'!C36/'Common size BS'!$C$4 -> 0.17104622 | D18: ='Balance Sheet'!D36/'Common size BS'!$D$4 -> 0.18892786 | E18: ='Balance Sheet'!E36/'Common size BS'!$E$4 -> 0.17978524 | F18: ='Balance Sheet'!F36/'Common size BS'!$F$4 -> 0.15959474 | G18: =AVERAGE(B18:F18) -> 0.16706757 | H18: =AVERAGE(C18:G18) -> 0.17328432
A19: Trade Receivables | B19: ='Balance Sheet'!B37/'Common size BS'!$B$4 -> 0.038984517 | C19: ='Balance Sheet'!C37/'Common size BS'!$C$4 -> 0.042902851 | D19: ='Balance Sheet'!D37/'Common size BS'!$D$4 -> 0.028668808 | E19: ='Balance Sheet'!E37/'Common size BS'!$E$4 -> 0.022907797 | F19: ='Balance Sheet'!F37/'Common size BS'!$F$4 -> 0.018826621 | G19: =AVERAGE(B19:F19) -> 0.030458119 | H19: =AVERAGE(C19:G19) -> 0.028752839
A20: Cash and Cash Equivalents | B20: ='Balance Sheet'!B38/'Common size BS'!$B$4 -> 0.023628855 | C20: ='Balance Sheet'!C38/'Common size BS'!$C$4 -> 0.055698634 | D20: ='Balance Sheet'!D38/'Common size BS'!$D$4 -> 0.046375874 | E20: ='Balance Sheet'!E38/'Common size BS'!$E$4 -> 0.031737287 | F20: ='Balance Sheet'!F38/'Common size BS'!$F$4 -> 0.041686459 | G20: =AVERAGE(B20:F20) -> 0.039825422 | H20: =AVERAGE(C20:G20) -> 0.043064735
A21: Short Term Loans & Advances | B21: ='Balance Sheet'!B39/'Common size BS'!$B$4 -> 2.2843512e-05 | C21: ='Balance Sheet'!C39/'Common size BS'!$C$4 -> 2.045924e-05 | D21: ='Balance Sheet'!D39/'Common size BS'!$D$4 -> 6.3884067e-06 | E21: ='Balance Sheet'!E39/'Common size BS'!$E$4 -> 5.8517282e-06 | F21: ='Balance Sheet'!F39/'Common size BS'!$F$4 -> 1.782424e-05 | G21: =AVERAGE(B21:F21) -> 1.4673425e-05 | H21: =AVERAGE(C21:G21) -> 1.3039408e-05
A22: Other Current Assets | B22: ='Balance Sheet'!B40/'Common size BS'!$B$4 -> 0.017935712 | C22: ='Balance Sheet'!C40/'Common size BS'!$C$4 -> 0.024721348 | D22: ='Balance Sheet'!D40/'Common size BS'!$D$4 -> 0.024316949 | E22: ='Balance Sheet'!E40/'Common size BS'!$E$4 -> 0.020907713 | F22: ='Balance Sheet'!F40/'Common size BS'!$F$4 -> 0.023074624 | G22: =AVERAGE(B22:F22) -> 0.022191269 | H22: =AVERAGE(C22:G22) -> 0.023042381
A23: Total Current Assets | B23: ='Balance Sheet'!B41/'Common size BS'!$B$4 -> 0.24605568 | C23: ='Balance Sheet'!C41/'Common size BS'!$C$4 -> 0.32425306 | D23: ='Balance Sheet'!D41/'Common size BS'!$D$4 -> 0.3008993 | E23: ='Balance Sheet'!E41/'Common size BS'!$E$4 -> 0.2580182 | F23: ='Balance Sheet'!F41/'Common size BS'!$F$4 -> 0.24478458 | G23: =AVERAGE(B23:F23) -> 0.27480217 | H23: =AVERAGE(C23:G23) -> 0.28055146
A24: {='Balance Sheet'!A4:A20} -> Shareholders' Funds
A25: Equity Share Capital | B25: ='Balance Sheet'!B5/'Common size BS'!$B$4 -> 0.0048940284 | C25: ='Balance Sheet'!C5/'Common size BS'!$C$4 -> 0.0042782583 | D25: ='Balance Sheet'!D5/'Common size BS'!$D$4 -> 0.0042400966 | E25: ='Balance Sheet'!E5/'Common size BS'!$E$4 -> 0.0045622999 | F25: ='Balance Sheet'!F5/'Common size BS'!$F$4 -> 0.0044647932 | G25: =AVERAGE(B25:F25) -> 0.0044878953 | H25: =AVERAGE(C25:G25) -> 0.0044066686
A26: Reserves and Surplus | B26: ='Balance Sheet'!B6/'Common size BS'!$B$4 -> 0.29529992 | C26: ='Balance Sheet'!C6/'Common size BS'!$C$4 -> 0.39664941 | D26: ='Balance Sheet'!D6/'Common size BS'!$D$4 -> 0.35365685 | E26: ='Balance Sheet'!E6/'Common size BS'!$E$4 -> 0.33204286 | F26: ='Balance Sheet'!F6/'Common size BS'!$F$4 -> 0.32184633 | G26: =AVERAGE(B26:F26) -> 0.33989907 | H26: =AVERAGE(C26:G26) -> 0.3488189
A27: Total Shareholders' Funds | B27: ='Balance Sheet'!B7/'Common size BS'!$B$4 -> 0.30019395 | C27: ='Balance Sheet'!C7/'Common size BS'!$C$4 -> 0.40092767 | D27: ='Balance Sheet'!D7/'Common size BS'!$D$4 -> 0.35789694 | E27: ='Balance Sheet'!E7/'Common size BS'!$E$4 -> 0.33660516 | F27: ='Balance Sheet'!F7/'Common size BS'!$F$4 -> 0.32631112 | G27: =AVERAGE(B27:F27) -> 0.34438697 | H27: =AVERAGE(C27:G27) -> 0.35322557
A28: Minority Interest | B28: ='Balance Sheet'!B8/'Common size BS'!$B$4 -> 0.013361534 | C28: ='Balance Sheet'!C8/'Common size BS'!$C$4 -> 0.0093027183 | D28: ='Balance Sheet'!D8/'Common size BS'!$D$4 -> 0.0072671945 | E28: ='Balance Sheet'!E8/'Common size BS'!$E$4 -> 0.0014518869 | F28: ='Balance Sheet'!F8/'Common size BS'!$F$4 -> 0.00065552401 | G28: =AVERAGE(B28:F28) -> 0.0064077715 | H28: =AVERAGE(C28:G28) -> 0.005017019
A29: Non-Current Liabilities
A30: Long Term Borrowings | B30: ='Balance Sheet'!B10/'Common size BS'!$B$4 -> 0.26847465 | C30: ='Balance Sheet'!C10/'Common size BS'!$C$4 -> 0.15682172 | D30: ='Balance Sheet'!D10/'Common size BS'!$D$4 -> 0.17861961 | E30: ='Balance Sheet'!E10/'Common size BS'!$E$4 -> 0.18863313 | F30: ='Balance Sheet'!F10/'Common size BS'!$F$4 -> 0.24535822 | G30: ='Balance Sheet'!G10/'Common size BS'!G4 -> 0.23031632 | H30: ='Balance Sheet'!H10/'Common size BS'!H4 -> 0.21675654
A31: Deferred Tax Liabilities (Net) | B31: ='Balance Sheet'!B11/'Common size BS'!$B$4 -> 0.037765025 | C31: ='Balance Sheet'!C11/'Common size BS'!$C$4 -> 0.043180837 | D31: ='Balance Sheet'!D11/'Common size BS'!$D$4 -> 0.049008939 | E31: ='Balance Sheet'!E11/'Common size BS'!$E$4 -> 0.047517276 | F31: ='Balance Sheet'!F11/'Common size BS'!$F$4 -> 0.051647883 | G31: =AVERAGE(B31:F31) -> 0.045823992 | H31: =AVERAGE(C31:G31) -> 0.047435786
A32: Other Long Term Liabilities | B32: ='Balance Sheet'!B12/'Common size BS'!$B$4 -> 0.071433093 | C32: ='Balance Sheet'!C12/'Common size BS'!$C$4 -> 0.055503781 | D32: ='Balance Sheet'!D12/'Common size BS'!$D$4 -> 0.052820978 | E32: ='Balance Sheet'!E12/'Common size BS'!$E$4 -> 0.046061074 | F32: ='Balance Sheet'!F12/'Common size BS'!$F$4 -> 0.047101843 | G32: =AVERAGE(B32:F32) -> 0.054584154 | H32: =AVERAGE(C32:G32) -> 0.051214366
A33: Long Term Provisions | B33: ='Balance Sheet'!B13/'Common size BS'!$B$4 -> 0.019173512 | C33: ='Balance Sheet'!C13/'Common size BS'!$C$4 -> 0.016906829 | D33: ='Balance Sheet'!D13/'Common size BS'!$D$4 -> 0.016581526 | E33: ='Balance Sheet'!E13/'Common size BS'!$E$4 -> 0.019837468 | F33: ='Balance Sheet'!F13/'Common size BS'!$F$4 -> 0.02078242 | G33: =AVERAGE(B33:F33) -> 0.018656351 | H33: =AVERAGE(C33:G33) -> 0.018552919
A34: Total Non-Current Liabilities | B34: ='Balance Sheet'!B14/'Common size BS'!$B$4 -> 0.39684628 | C34: ='Balance Sheet'!C14/'Common size BS'!$C$4 -> 0.27241317 | D34: ='Balance Sheet'!D14/'Common size BS'!$D$4 -> 0.29703105 | E34: ='Balance Sheet'!E14/'Common size BS'!$E$4 -> 0.30204895 | F34: ='Balance Sheet'!F14/'Common size BS'!$F$4 -> 0.36489036 | G34: =AVERAGE(B34:F34) -> 0.32664596 | H34: =AVERAGE(C34:G34) -> 0.3126059
A35: Current Liabilities
A36: Short Term Borrowings | B36: ='Balance Sheet'!B16/'Common size BS'!$B$4 -> 0.061170635 | C36: ='Balance Sheet'!C16/'Common size BS'!$C$4 -> 0.084305416 | D36: ='Balance Sheet'!D16/'Common size BS'!$D$4 -> 0.092254737 | E36: ='Balance Sheet'!E16/'Common size BS'!$E$4 -> 0.10970963 | F36: ='Balance Sheet'!F16/'Common size BS'!$F$4 -> 0.073057909 | G36: ='Balance Sheet'!G16/'Common size BS'!G4 -> 0.068579032 | H36: ='Balance Sheet'!H16/'Common size BS'!H4 -> 0.064541469
A37: Trade Payables | B37: ='Balance Sheet'!B17/'Common size BS'!$B$4 -> 0.10611604 | C37: ='Balance Sheet'!C17/'Common size BS'!$C$4 -> 0.12879817 | D37: ='Balance Sheet'!D17/'Common size BS'!$D$4 -> 0.13135307 | E37: ='Balance Sheet'!E17/'Common size BS'!$E$4 -> 0.12959625 | F37: ='Balance Sheet'!F17/'Common size BS'!$F$4 -> 0.10492099 | G37: =AVERAGE(B37:F37) -> 0.1201569 | H37: =AVERAGE(C37:G37) -> 0.12296508
A38: Other Current Liabilities | B38: ='Balance Sheet'!B18/'Common size BS'!$B$4 -> 0.10300156 | C38: ='Balance Sheet'!C18/'Common size BS'!$C$4 -> 0.094554024 | D38: ='Balance Sheet'!D18/'Common size BS'!$D$4 -> 0.10071632 | E38: ='Balance Sheet'!E18/'Common size BS'!$E$4 -> 0.10676679 | F38: ='Balance Sheet'!F18/'Common size BS'!$F$4 -> 0.11624726 | G38: =AVERAGE(B38:F38) -> 0.10425719 | H38: =AVERAGE(C38:G38) -> 0.10450832
A39: Short Term Provisions | B39: ='Balance Sheet'!B19/'Common size BS'!$B$4 -> 0.019310001 | C39: ='Balance Sheet'!C19/'Common size BS'!$C$4 -> 0.0096988358 | D39: ='Balance Sheet'!D19/'Common size BS'!$D$4 -> 0.013480684 | E39: ='Balance Sheet'!E19/'Common size BS'!$E$4 -> 0.013821343 | F39: ='Balance Sheet'!F19/'Common size BS'!$F$4 -> 0.01391683 | G39: =AVERAGE(B39:F39) -> 0.014045539 | H39: =AVERAGE(C39:G39) -> 0.012992646
A40: Total Current Liabilities | B40: ='Balance Sheet'!B20/'Common size BS'!$B$4 -> 0.28959824 | C40: ='Balance Sheet'!C20/'Common size BS'!$C$4 -> 0.31735644 | D40: ='Balance Sheet'!D20/'Common size BS'!$D$4 -> 0.33780481 | E40: ='Balance Sheet'!E20/'Common size BS'!$E$4 -> 0.35989401 | F40: ='Balance Sheet'!F20/'Common size BS'!$F$4 -> 0.30814299 | G40: =AVERAGE(B40:F40) -> 0.3225593 | H40: =AVERAGE(C40:G40) -> 0.32915151

Sheet Common size pl
A1: TATA STEEL LIMITED —CommanSize Profit & Loss Statement (₹ in Crores)
A2: Particulars | B2: FY '21 | C2: FY '22 | D2: FY '23 | E2: FY '24 | F2: FY '25 | G2: Forecast FY'26 | H2: Forecast FY'27
A3: Sales Turnover | B3: {='P & L Statement'!B4:F4} -> 156477.4 | C3: 243959.17 | D3: 243352.69 | E3: 229170.78 | F3: 218542.51 | G3: ='P & L Statement'!G4 -> 237578.43 | H3: ='P & L Statement'!H4 -> 258272.45
A4: {='P & L Statement'!A5:A32} -> Non-operating income | B4: ='P & L Statement'!B5/'Common size pl'!$B$3 -> -0.049686536 | C4: ='P & L Statement'!C5/'Common size pl'!$C$3 -> 0.0041696322 | D4: ='P & L Statement'!D5/'Common size pl'!$D$3 -> -0.036288319 | E4: ='P & L Statement'!E5/'Common size pl'!$E$3 -> -0.046588837 | F4: ='P & L Statement'!F5/'Common size pl'!$F$3 -> 0.0029074435 | G4: =AVERAGE(B4:F4) -> -0.025097323 | H4: =AVERAGE(C4:G4) -> -0.020179481
A5: Stock Adjustments | B5: ='P & L Statement'!B6/'Common size pl'!$B$3 -> -0.0096932209 | C5: ='P & L Statement'!C6/'Common size pl'!$C$3 -> 0.031144023 | D5: ='P & L Statement'!D6/'Common size pl'!$D$3 -> 0.01380256 | E5: ='P & L Statement'!E6/'Common size pl'!$E$3 -> -0.019240455 | F5: ='P & L Statement'!F6/'Common size pl'!$F$3 -> 0.00044224806 | G5: =AVERAGE(B5:F5) -> 0.003291031 | H5: =AVERAGE(C5:G5) -> 0.0058878814
A6: Total Income | B6: ='P & L Statement'!B7/'Common size pl'!$B$3 -> 0.94062024 | C6: ='P & L Statement'!C7/'Common size pl'!$C$3 -> 1.0353137 | D6: ='P & L Statement'!D7/'Common size pl'!$D$3 -> 0.97751424 | E6: ='P & L Statement'!E7/'Common size pl'!$E$3 -> 0.93417071 | F6: ='P & L Statement'!F7/'Common size pl'!$F$3 -> 1.0033497 | G6: ='P & L Statement'!G7/G3 -> 0.97819371 | H6: ='P & L Statement'!H7/H3 -> 0.9857084
A7: EXPENDITURE
A8: Raw Materials | B8: ='P & L Statement'!B9/'Common size pl'!$B$3 -> 0.4215888 | C8: ='P & L Statement'!C9/'Common size pl'!$C$3 -> 0.43874354 | D8: ='P & L Statement'!D9/'Common size pl'!$D$3 -> 0.56737515 | E8: ='P & L Statement'!E9/'Common size pl'!$E$3 -> 0.50725245 | F8: ='P & L Statement'!F9/'Common size pl'!$F$3 -> 0.48538008 | G8: =AVERAGE(B8:F8) -> 0.48406801 | H8: =AVERAGE(C8:G8) -> 0.49656385
A9: Power & Fuel Cost | B9: ='P & L Statement'!B10/'Common size pl'!$B$3 -> 0.036480795 | C9: ='P & L Statement'!C10/'Common size pl'!$C$3 -> 0.032908335 | D9: ='P & L Statement'!D10/'Common size pl'!$D$3 -> 0.039148571 | E9: ='P & L Statement'!E10/'Common size pl'!$E$3 -> 0.043949102 | F9: ='P & L Statement'!F10/'Common size pl'!$F$3 -> 0.060056279 | G9: =AVERAGE(B9:F9) -> 0.042508616 | H9: =AVERAGE(C9:G9) -> 0.043714181
A10: Employee Cost | B10: ='P & L Statement'!B11/'Common size pl'!$B$3 -> 0.12723122 | C10: ='P & L Statement'!C11/'Common size pl'!$C$3 -> 0.095360629 | D10: ='P & L Statement'!D11/'Common size pl'!$D$3 -> 0.092126863 | E10: ='P & L Statement'!E11/'Common size pl'!$E$3 -> 0.10694897 | F10: ='P & L Statement'!F11/'Common size pl'!$F$3 -> 0.11388626 | G10: =AVERAGE(B10:F10) -> 0.10711079 | H10: =AVERAGE(C10:G10) -> 0.1030867
A11: Miscellaneous Expenses | B11: ='P & L Statement'!B12/'Common size pl'!$B$3 -> 0.21006241 | C11: ='P & L Statement'!C12/'Common size pl'!$C$3 -> 0.20388326 | D11: ='P & L Statement'!D12/'Common size pl'!$D$3 -> 0.18242215 | E11: ='P & L Statement'!E12/'Common size pl'!$E$3 -> 0.22527593 | F11: ='P & L Statement'!F12/'Common size pl'!$F$3 -> 0.22535977 | G11: =AVERAGE(B11:F11) -> 0.2094007 | H11: =AVERAGE(C11:G11) -> 0.20926836
A12: COGS | B12: ='P & L Statement'!B13/'Common size pl'!$B$3 -> 0.79536323 | C12: ='P & L Statement'!C13/'Common size pl'!$C$3 -> 0.77089576 | D12: ='P & L Statement'!D13/'Common size pl'!$D$3 -> 0.88107273 | E12: ='P & L Statement'!E13/'Common size pl'!$E$3 -> 0.88342646 | F12: ='P & L Statement'!F13/'Common size pl'!$F$3 -> 0.88468239 | G12: =AVERAGE(B12:F12) -> 0.84308811 | H12: =AVERAGE(C12:G12) -> 0.85263309
A13: PROFITABILITY
A14: Operating Profit (EBITDA) | B14: ='P & L Statement'!B15/'Common size pl'!$B$3 -> 0.14525701 | C14: ='P & L Statement'!C15/'Common size pl'!$C$3 -> 0.26441789 | D14: ='P & L Statement'!D15/'Common size pl'!$D$3 -> 0.096441506 | E14: ='P & L Statement'!E15/'Common size pl'!$E$3 -> 0.050744253 | F14: ='P & L Statement'!F15/'Common size pl'!$F$3 -> 0.1186673 | G14: ='P & L Statement'!G15/'Common size pl'!$G$3 -> 0.13510559 | H14: ='P & L Statement'!H15/$H$3 -> 0.13307531
A15: Less: Interest | B15: ='P & L Statement'!B16/'Common size pl'!$B$3 -> 0.048612196 | C15: ='P & L Statement'!C16/'Common size pl'!$C$3 -> 0.022389812 | D15: ='P & L Statement'!D16/'Common size pl'!$D$3 -> 0.02588301 | E15: ='P & L Statement'!E16/'Common size pl'!$E$3 -> 0.032759717 | F15: ='P & L Statement'!F16/'Common size pl'!$F$3 -> 0.03359049 | G15: ='P & L Statement'!G16/'Common size pl'!$G$3 -> 0.03089906 | H15: ='P & L Statement'!H16/$H$3 -> 0.02842328
A16: PBDT | B16: ='P & L Statement'!B17/'Common size pl'!$B$3 -> 0.096644819 | C16: ='P & L Statement'!C17/'Common size pl'!$C$3 -> 0.24202808 | D16: ='P & L Statement'!D17/'Common size pl'!$D$3 -> 0.070558497 | E16: ='P & L Statement'!E17/'Common size pl'!$E$3 -> 0.017984535 | F16: ='P & L Statement'!F17/'Common size pl'!$F$3 -> 0.085076812 | G16: ='P & L Statement'!G17/'Common size pl'!$G$3 -> 0.10420653 | H16: ='P & L Statement'!H17/$H$3 -> 0.10465203
A17: Less: Depreciation | B17: ='P & L Statement'!B18/'Common size pl'!$B$3 -> 0.059009416 | C17: ='P & L Statement'!C18/'Common size pl'!$C$3 -> 0.03730489 | D17: ='P & L Statement'!D18/'Common size pl'!$D$3 -> 0.038360784 | E17: ='P & L Statement'!E18/'Common size pl'!$E$3 -> 0.043121379 | F17: ='P & L Statement'!F18/'Common size pl'!$F$3 -> 0.047685597 | G17: =AVERAGE(B17:F17) -> 0.045096413 | H17: =AVERAGE(C17:G17) -> 0.042313813
A18: Profit Before Tax (PBT) | B18: ='P & L Statement'!B19/'Common size pl'!$B$3 -> 0.037635403 | C18: ='P & L Statement'!C19/'Common size pl'!$C$3 -> 0.20472319 | D18: ='P & L Statement'!D19/'Common size pl'!$D$3 -> 0.032197713 | E18: ='P & L Statement'!E19/'Common size pl'!$E$3 -> -0.025136843 | F18: ='P & L Statement'!F19/'Common size pl'!$F$3 -> 0.037391215 | G18: ='P & L Statement'!G19/'Common size pl'!$G$3 -> 0.059110121 | H18: ='P & L Statement'!H19/'Common size pl'!$H$3 -> 0.062338218
A19: Tax (incl. Deferred Tax) | B19: ='P & L Statement'!B20/'Common size pl'!$B$3 -> 0.036132374 | C19: ='P & L Statement'!C20/'Common size pl'!$C$3 -> 0.034749872 | D19: ='P & L Statement'!D20/'Common size pl'!$D$3 -> 0.041749158 | E19: ='P & L Statement'!E20/'Common size pl'!$E$3 -> 0.016418193 | F19: ='P & L Statement'!F20/'Common size pl'!$F$3 -> 0.023972865 | G19: ='P & L Statement'!G20/'Common size pl'!$G$3 -> 0.017733036 | H19: ='P & L Statement'!H20/'Common size pl'!$H$3 -> 0.018701465
A20: PAT | B20: ='P & L Statement'!B21/'Common size pl'!$B$3 -> 0.0015030286 | C20: ='P & L Statement'!C21/'Common size pl'!$C$3 -> 0.16997332 | D20: ='P & L Statement'!D21/'Common size pl'!$D$3 -> -0.0095514457 | E20: ='P & L Statement'!E21/'Common size pl'!$E$3 -> -0.041555036 | F20: ='P & L Statement'!F21/'Common size pl'!$F$3 -> 0.013418351 | G20: ='P & L Statement'!G21/'Common size pl'!$G$3 -> 0.041377085 | H20: ='P & L Statement'!H21/'Common size pl'!$H$3 -> 0.043636752
A21: Less: Non-Controlling Interest | B21: ='P & L Statement'!B22/'Common size pl'!$B$3 -> -0.044272783 | C21: ='P & L Statement'!C22/'Common size pl'!$C$3 -> 0.0080414276 | D21: ='P & L Statement'!D22/'Common size pl'!$D$3 -> -0.043832061 | E21: ='P & L Statement'!E22/'Common size pl'!$E$3 -> -0.022445008 | F21: ='P & L Statement'!F22/'Common size pl'!$F$3 -> -0.00136001 | G21: =AVERAGE(B21:F21) -> -0.020773687 | H21: =AVERAGE(C21:G21) -> -0.016073868
A22: Reported Net Profit | B22: ='P & L Statement'!B23/'Common size pl'!$B$3 -> 0.045775812 | C22: ='P & L Statement'!C23/'Common size pl'!$C$3 -> 0.16193189 | D22: ='P & L Statement'!D23/'Common size pl'!$D$3 -> 0.034280616 | E22: ='P & L Statement'!E23/'Common size pl'!$E$3 -> -0.019110028 | F22: ='P & L Statement'!F23/'Common size pl'!$F$3 -> 0.014778361 | G22: ='P & L Statement'!G23/'Common size pl'!$G$3 -> 0.062150772 | H22: ='P & L Statement'!H23/'Common size pl'!$H$3 -> 0.05971062
A23: PER SHARE DATA
A24: Shares in Issue (Lakhs) | B24: ='P & L Statement'!B25/'Common size pl'!$B$3 -> 0.076876597 | C24: ='P & L Statement'!C25/'Common size pl'!$C$3 -> 0.050056614 | D24: ='P & L Statement'!D25/'Common size pl'!$D$3 -> 0.050173475 | E24: ='P & L Statement'!E25/'Common size pl'!$E$3 -> 0.052821088 | F24: ='P & L Statement'!F25/'Common size pl'!$F$3 -> 0.57068293 | G24: =AVERAGE(B24:F24) -> 0.16012214 | H24: =AVERAGE(C24:G24) -> 0.17677125
A25: Earnings Per Share (₹) | B25: ='P & L Statement'!B26/'Common size pl'!$B$3 -> 0.00038053121 | C25: ='P & L Statement'!C26/'Common size pl'!$C$3 -> 0.0013260313 | D25: ='P & L Statement'!D26/'Common size pl'!$D$3 -> 0.00028076197 | E25: ='P & L Statement'!E26/'Common size pl'!$E$3 -> -0.00015786823 | F25: ='P & L Statement'!F26/'Common size pl'!$F$3 -> 1.1849375e-05 | G25: =AVERAGE(B25:F25) -> 0.00036826113 | H25: =AVERAGE(C25:G25) -> 0.00036580711
A26: Book Value Per Share (₹) | B26: ='P & L Statement'!B27/'Common size pl'!$B$3 -> 0.0039026083 | C26: ='P & L Statement'!C27/'Common size pl'!$C$3 -> 0.0038414215 | D26: ='P & L Statement'!D27/'Common size pl'!$D$3 -> 0.000346945 | E26: ='P & L Statement'!E27/'Common size pl'!$E$3 -> 0.00032198695 | F26: ='P & L Statement'!F27/'Common size pl'!$F$3 -> 0.0003344887 | G26: =AVERAGE(B26:F26) -> 0.0017494901 | H26: =AVERAGE(C26:G26) -> 0.0013188664
A27: Equity Dividend (₹ Cr) | B27: ='P & L Statement'!B28/'Common size pl'!$B$3 -> 0.0073157529 | C27: ='P & L Statement'!C28/'Common size pl'!$C$3 -> 0.012314192 | D27: ='P & L Statement'!D28/'Common size pl'!$D$3 -> 0.025588992 | E27: ='P & L Statement'!E28/'Common size pl'!$E$3 -> 0.019242375 | F27: ='P & L Statement'!F28/'Common size pl'!$F$3 -> 0.020544607 | G27: =AVERAGE(B27:F27) -> 0.017001184 | H27: =AVERAGE(C27:G27) -> 0.01893827
A28: OTHER METRICS
A29: Share of P/L of Associates | B29: ='P & L Statement'!B30/'Common size pl'!$B$3 -> -0.0020919315 | C29: ='P & L Statement'!C30/'Common size pl'!$C$3 -> -0.0026609371 | D29: ='P & L Statement'!D30/'Common size pl'!$D$3 -> -0.0017181647 | E29: ='P & L Statement'!E30/'Common size pl'!$E$3 -> 0.0002529991 | F29: ='P & L Statement'!F30/'Common size pl'!$F$3 -> -0.00087310245 | G29: =AVERAGE(B29:F29) -> -0.0014182273 | H29: =AVERAGE(C29:G29) -> -0.0012834865
A30: Net P/L after MI & Associates | B30: ='P & L Statement'!B31/'Common size pl'!$B$3 -> 0.059005006 | C30: ='P & L Statement'!C31/'Common size pl'!$C$3 -> 0.17168193 | D30: ='P & L Statement'!D31/'Common size pl'!$D$3 -> 0.032718315 | E30: ='P & L Statement'!E31/'Common size pl'!$E$3 -> 0.012673823 | F30: ='P & L Statement'!F31/'Common size pl'!$F$3 -> 0.018433119 | G30: =AVERAGE(B30:F30) -> 0.058902438 | H30: =AVERAGE(C30:G30) -> 0.058881924
A31: Total Value Addition | B31: ='P & L Statement'!B32/'Common size pl'!$B$3 -> 0.37377442 | C31: ='P & L Statement'!C32/'Common size pl'!$C$3 -> 0.33215222 | D31: ='P & L Statement'!D32/'Common size pl'!$D$3 -> 0.31369758 | E31: ='P & L Statement'!E32/'Common size pl'!$E$3 -> 0.376174 | F31: ='P & L Statement'!F32/'Common size pl'!$F$3 -> 0.39930231 | G31: =AVERAGE(B31:F31) -> 0.35902011 | H31: =AVERAGE(C31:G31) -> 0.35606925

Sheet Ratio analysis
A1: TATA STEEL LIMITED —Ratio Analysis (₹ in Crores)
A2: Sr.no | B2: Particulars | C2: FY '21 | D2: FY '22 | E2: FY '23 | F2: FY '24 | G2: FY '25 | H2: Forecast FY'26 | I2: Forecast FY'27
B3: Liquidity Ratio
A4: 1 | B4: Current Ratio | C4: ='Balance Sheet'!B41/'Balance Sheet'!B20 -> 0.84964496 | D4: ='Balance Sheet'!C41/'Balance Sheet'!C20 -> 1.0217315 | E4: ='Balance Sheet'!D41/'Balance Sheet'!D20 -> 0.890749 | F4: ='Balance Sheet'!E41/'Balance Sheet'!E20 -> 0.7169283 | G4: ='Balance Sheet'!F41/'Balance Sheet'!F20 -> 0.79438634 | H4: ='Balance Sheet'!G41/'Balance Sheet'!G20 -> 0.75443665 | I4: ='Balance Sheet'!H41/'Balance Sheet'!H20 -> 0.14363991
A5: 2 | B5: Quick Ratio | C5: =('Balance Sheet'!B38+'Balance Sheet'!B37+'Balance Sheet'!B35)/'Balance Sheet'!B20 -> 0.31807285 | D5: =('Balance Sheet'!C38+'Balance Sheet'!C37+'Balance Sheet'!C35)/'Balance Sheet'!C20 -> 0.40479732 | E5: =('Balance Sheet'!D38+'Balance Sheet'!D37+'Balance Sheet'!D35)/'Balance Sheet'!D20 -> 0.25946376 | F5: =('Balance Sheet'!E38+'Balance Sheet'!E37+'Balance Sheet'!E35)/'Balance Sheet'!E20 -> 0.15926744 | G5: =('Balance Sheet'!F38+'Balance Sheet'!F37+'Balance Sheet'!F35)/'Balance Sheet'!F20 -> 0.20152137 | H5: =('Balance Sheet'!G38+'Balance Sheet'!G37+'Balance Sheet'!G35)/'Balance Sheet'!G20 -> 0.15279222 | I5: =('Balance Sheet'!H38+'Balance Sheet'!H37+'Balance Sheet'!H35)/'Balance Sheet'!H20 -> -0.46645045
A6: 3 | B6: Cash Ratio | C6: =('Balance Sheet'!B38+'Balance Sheet'!B35)/'Balance Sheet'!B20 -> 0.18345698 | D6: =('Balance Sheet'!C38+'Balance Sheet'!C35)/'Balance Sheet'!C20 -> 0.26960911 | E6: =('Balance Sheet'!D38+'Balance Sheet'!D35)/'Balance Sheet'!D20 -> 0.17459579 | F6: =('Balance Sheet'!E38+'Balance Sheet'!E35)/'Balance Sheet'!E20 -> 0.095615927 | G6: =('Balance Sheet'!F38+'Balance Sheet'!F35)/'Balance Sheet'!F20 -> 0.14042434 | H6: =('Balance Sheet'!G38+'Balance Sheet'!G35)/'Balance Sheet'!G20 -> 0.090318777 | I6: =('Balance Sheet'!H38+'Balance Sheet'!H35)/'Balance Sheet'!H20 -> -0.53025128
A7: 4 | B7: Defensive Internal Ratio | C7: =('Balance Sheet'!B38+'Balance Sheet'!B37+'Balance Sheet'!B35)/(('P & L Statement'!B13-'P & L Statement'!B18)/365) -> 71.404593 | D7: =('Balance Sheet'!C38+'Balance Sheet'!C37+'Balance Sheet'!C35)/(('P & L Statement'!C13-'P & L Statement'!C18)/365) -> 74.787687 | E7: =('Balance Sheet'!D38+'Balance Sheet'!D37+'Balance Sheet'!D35)/(('P & L Statement'!D13-'P & L Statement'!D18)/365) -> 44.930926 | F7: =('Balance Sheet'!E38+'Balance Sheet'!E37+'Balance Sheet'!E35)/(('P & L Statement'!E13-'P & L Statement'!E18)/365) -> 29.705309 | G7: =('Balance Sheet'!F38+'Balance Sheet'!F37+'Balance Sheet'!F35)/(('P & L Statement'!F13-'P & L Statement'!F18)/365) -> 34.619825 | H7: =('Balance Sheet'!G38+'Balance Sheet'!G37+'Balance Sheet'!G35)/(('P & L Statement'!G13-'P & L Statement'!G18)/365) -> 26.924959 | I7: =('Balance Sheet'!H38+'Balance Sheet'!H37+'Balance Sheet'!H35)/(('P & L Statement'!H13-'P & L Statement'!H18)/365) -> -79.263024
A8: 5 | B8: Cash Conversion Cycle | C8: =(AVERAGE('Balance Sheet'!A36,'Balance Sheet'!B36)/('P & L Statement'!B13/365))+(AVERAGE('Balance Sheet'!A37,'Balance Sheet'!B37)/('P & L Statement'!B4/365))-(AVERAGE('Balance Sheet'!A17,'Balance Sheet'!B17)/('P & L Statement'!B13/365)) -> 43.687862 | D8: =(AVERAGE('Balance Sheet'!B36,'Balance Sheet'!C36)/('P & L Statement'!C13/365))+(AVERAGE('Balance Sheet'!B37,'Balance Sheet'!C37)/('P & L Statement'!C4/365))-(AVERAGE('Balance Sheet'!B17,'Balance Sheet'!C17)/('P & L Statement'!C13/365)) -> 35.092859 | E8: =(AVERAGE('Balance Sheet'!C36,'Balance Sheet'!D36)/('P & L Statement'!D13/365))+(AVERAGE('Balance Sheet'!C37,'Balance Sheet'!D37)/('P & L Statement'!D4/365))-(AVERAGE('Balance Sheet'!C17,'Balance Sheet'!D17)/('P & L Statement'!D13/365)) -> 39.755928 | F8: =(AVERAGE('Balance Sheet'!D36,'Balance Sheet'!E36)/('P & L Statement'!E13/365))+(AVERAGE('Balance Sheet'!D37,'Balance Sheet'!E37)/('P & L Statement'!E4/365))-(AVERAGE('Balance Sheet'!D17,'Balance Sheet'!E17)/('P & L Statement'!E13/365)) -> 38.882095 | G8: =(AVERAGE('Balance Sheet'!E36,'Balance Sheet'!F36)/('P & L Statement'!F13/365))+(AVERAGE('Balance Sheet'!E37,'Balance Sheet'!F37)/('P & L Statement'!F4/365))-(AVERAGE('Balance Sheet'!E17,'Balance Sheet'!F17)/('P & L Statement'!F13/365)) -> 36.995549 | H8: =(AVERAGE('Balance Sheet'!F36,'Balance Sheet'!G36)/('P & L Statement'!G13/365))+(AVERAGE('Balance Sheet'!F37,'Balance Sheet'!G37)/('P & L Statement'!G4/365))-(AVERAGE('Balance Sheet'!F17,'Balance Sheet'!G17)/('P & L Statement'!G13/365)) -> 37.481693 | I8: =(AVERAGE('Balance Sheet'!G36,'Balance Sheet'!H36)/('P & L Statement'!H13/365))+(AVERAGE('Balance Sheet'!G37,'Balance Sheet'!H37)/('P & L Statement'!H4/365))-(AVERAGE('Balance Sheet'!G17,'Balance Sheet'!H17)/('P & L Statement'!H13/365)) -> 37.156504
B9: Solvency Ratio
A10: 6 | B10: Debt to Equity Ratio | C10: =('Balance Sheet'!B10+'Balance Sheet'!B16)/'Balance Sheet'!B7 -> 1.0981077 | D10: =('Balance Sheet'!C10+'Balance Sheet'!C16)/'Balance Sheet'!C7 -> 0.60142303 | E10: =('Balance Sheet'!D10+'Balance Sheet'!D16)/'Balance Sheet'!D7 -> 0.75685012 | F10: =('Balance Sheet'!E10+'Balance Sheet'!E16)/'Balance Sheet'!E7 -> 0.88632853 | G10: =('Balance Sheet'!F10+'Balance Sheet'!F16)/'Balance Sheet'!F7 -> 0.97580532 | H10: =('Balance Sheet'!G10+'Balance Sheet'!G16)/'Balance Sheet'!G7 -> 0.87308272 | I10: =('Balance Sheet'!H10+'Balance Sheet'!H16)/'Balance Sheet'!H7 -> 0.7913059
A11: 7 | B11: Financial Leverage | C11: ='Balance Sheet'!B42/'Balance Sheet'!B7 -> 3.3311797 | D11: ='Balance Sheet'!C42/'Balance Sheet'!C7 -> 2.4942155 | E11: ='Balance Sheet'!D42/'Balance Sheet'!D7 -> 2.7941004 | F11: ='Balance Sheet'!E42/'Balance Sheet'!E7 -> 2.9708398 | G11: ='Balance Sheet'!F42/'Balance Sheet'!F7 -> 3.06456 | H11: ='Balance Sheet'!G42/'Balance Sheet'!G7 -> 2.9210314 | I11: ='Balance Sheet'!H42/'Balance Sheet'!H7 -> 2.8130519
A12: 8 | B12: Interest Coverage | C12: =('P & L Statement'!B15-'P & L Statement'!B18)/'P & L Statement'!B16 -> 1.7741967 | D12: =('P & L Statement'!C15-'P & L Statement'!C18)/'P & L Statement'!C16 -> 10.143587 | E12: =('P & L Statement'!D15-'P & L Statement'!D18)/'P & L Statement'!D16 -> 2.243971 | F12: =('P & L Statement'!E15-'P & L Statement'!E18)/'P & L Statement'!E16 -> 0.23269047 | G12: =('P & L Statement'!F15-'P & L Statement'!F18)/'P & L Statement'!F16 -> 2.1131488 | H12: =('P & L Statement'!G15-'P & L Statement'!G18)/'P & L Statement'!G16 -> 2.9130071 | I12: =('P & L Statement'!H15-'P & L Statement'!H18)/'P & L Statement'!H16 -> 3.1932099
B13: Activity Ratio
A14: 9 | B14: Receivable Turnover ratio | C14: =('P & L Statement'!B4)/('Balance Sheet'!B37) -> 16.402518 | D14: =('P & L Statement'!C4)/('Balance Sheet'!B37+'Balance Sheet'!C37/2) -> 15.575453 | E14: =('P & L Statement'!D4)/('Balance Sheet'!C37+'Balance Sheet'!D37/2) -> 14.861188 | F14: =('P & L Statement'!E4)/('Balance Sheet'!D37+'Balance Sheet'!E37/2) -> 20.122107 | G14: =('P & L Statement'!F4)/('Balance Sheet'!E37+'Balance Sheet'!F37/2) -> 24.573119 | H14: =('P & L Statement'!G4)/('Balance Sheet'!F37+'Balance Sheet'!G37/2) -> 29.261396 | I14: =('P & L Statement'!H4)/('Balance Sheet'!G37+'Balance Sheet'!H37/2) -> 29.261396
A15: 10 | B15: Days sales Outstanding | C15: =365/C14 -> 22.252681 | D15: =365/D14 -> 23.434311 | E15: =365/E14 -> 24.560621 | F15: =365/F14 -> 18.139253 | G15: =365/G14 -> 14.853629 | H15: =365/H14 -> 12.473772 | I15: =365/I14 -> 12.473772
A16: 11 | B16: Inventory Turnover ratio | C16: ='P & L Statement'!B13/'Balance Sheet'!B37 -> 13.04596 | D16: ='P & L Statement'!C13/('Balance Sheet'!B36+'Balance Sheet'!C37/2) -> 4.7733255 | E16: ='P & L Statement'!D13/('Balance Sheet'!C36+'Balance Sheet'!D37/2) -> 4.0490884 | F16: ='P & L Statement'!E13/('Balance Sheet'!D36+'Balance Sheet'!E37/2) -> 3.5180843 | G16: ='P & L Statement'!F13/('Balance Sheet'!E36+'Balance Sheet'!F37/2) -> 3.7333442 | H16: ='P & L Statement'!G13/('Balance Sheet'!F36+'Balance Sheet'!G37/2) -> 4.22136 | I16: ='P & L Statement'!H13/('Balance Sheet'!G36+'Balance Sheet'!H37/2) -> 4.2691519
A17: 12 | B17: Days on Inventory in hand | C17: =365/C16 -> 27.97801 | D17: =365/D16 -> 76.466607 | E17: =365/E16 -> 90.143746 | F17: =365/F16 -> 103.74965 | G17: =365/G16 -> 97.767574 | H17: =365/H16 -> 86.465025 | I17: =365/I16 -> 85.497074
A18: 13 | B18: Fixed Asset Turnover | C18: ='P & L Statement'!B4/'Balance Sheet'!B28 -> 1.0401462 | D18: ='P & L Statement'!B4/('Balance Sheet'!B28+'Balance Sheet'!C28/2) -> 0.69253422 | E18: ='P & L Statement'!C4/('Balance Sheet'!C28+'Balance Sheet'!D28/2) -> 1.028762 | F18: ='P & L Statement'!D4/('Balance Sheet'!D28+'Balance Sheet'!E28/2) -> 0.93258182 | G18: ='P & L Statement'!E4/('Balance Sheet'!E28+'Balance Sheet'!F28/2) -> 0.84654344 | H18: ='P & L Statement'!F4/('Balance Sheet'!F28+'Balance Sheet'!G28/2) -> 0.75889503 | I18: ='P & L Statement'!G4/('Balance Sheet'!G28+'Balance Sheet'!H28/2) -> 0.69805515
A19: 14 | B19: Payable Ratio | C19: ='P & L Statement'!B13/'Balance Sheet'!B17 -> 4.7927763 | D19: ='P & L Statement'!C13/('Balance Sheet'!B17+'Balance Sheet'!C17/2) -> 4.2405278 | E19: ='P & L Statement'!D13/('Balance Sheet'!C17+'Balance Sheet'!D17/2) -> 3.850701 | F19: ='P & L Statement'!E13/('Balance Sheet'!D17+'Balance Sheet'!E17/2) -> 3.6445725 | G19: ='P & L Statement'!F13/('Balance Sheet'!E17+'Balance Sheet'!F17/2) -> 3.8597239 | H19: ='P & L Statement'!G13/('Balance Sheet'!F17+'Balance Sheet'!G17/2) -> 4.4266787 | I19: ='P & L Statement'!H13/('Balance Sheet'!G17+'Balance Sheet'!H17/2) -> 4.4767951
A20: 15 | B20: Payable Days | C20: =365/C19 -> 76.156277 | D20: =365/D19 -> 86.074191 | E20: =365/E19 -> 94.787937 | F20: =365/F19 -> 100.14892 | G20: =365/G19 -> 94.56635 | H20: =365/H19 -> 82.454596 | I20: =365/I19 -> 81.531541
B21: Profitability Ratio
A22: 16 | B22: Net Profit Margin | C22: ='P & L Statement'!B21/'P & L Statement'!B4 -> 0.0015030286 | D22: ='P & L Statement'!C21/'P & L Statement'!C4 -> 0.16997332 | E22: ='P & L Statement'!D21/'P & L Statement'!D4 -> -0.0095514457 | F22: ='P & L Statement'!E21/'P & L Statement'!E4 -> -0.041555036 | G22: ='P & L Statement'!F21/'P & L Statement'!F4 -> 0.013418351 | H22: ='P & L Statement'!G21/'P & L Statement'!G4 -> 0.041377085 | I22: ='P & L Statement'!H21/'P & L Statement'!H4 -> 0.043636752
A23: 17 | B23: Operating Profit Margin | C23: =('P & L Statement'!B15-'P & L Statement'!B18)/'P & L Statement'!B4 -> 0.086247599 | D23: =('P & L Statement'!C15-'P & L Statement'!C18)/'P & L Statement'!C4 -> 0.227113 | E23: =('P & L Statement'!D15-'P & L Statement'!D18)/'P & L Statement'!D4 -> 0.058080722 | F23: =('P & L Statement'!E15-'P & L Statement'!E18)/'P & L Statement'!E4 -> 0.0076228741 | G23: =('P & L Statement'!F15-'P & L Statement'!F18)/'P & L Statement'!F4 -> 0.070981705 | H23: =('P & L Statement'!G15-'P & L Statement'!G18)/'P & L Statement'!G4 -> 0.090009181 | I23: =('P & L Statement'!H15-'P & L Statement'!H18)/'P & L Statement'!H4 -> 0.090761497
A24: 18 | B24: Return On Asset | C24: ='P & L Statement'!B21/'Balance Sheet'!B42 -> 0.00096110297 | D24: ='P & L Statement'!C21/('Balance Sheet'!B42+'Balance Sheet'!C42/2) -> 0.10702945 | E24: ='P & L Statement'!D21/('Balance Sheet'!C42+'Balance Sheet'!D42/2) -> -0.005412353 | F24: ='P & L Statement'!E21/('Balance Sheet'!D42+'Balance Sheet'!E42/2) -> -0.02242159 | G24: ='P & L Statement'!F21/('Balance Sheet'!E42+'Balance Sheet'!F42/2) -> 0.0070983579 | H24: ='P & L Statement'!G21/('Balance Sheet'!F42+'Balance Sheet'!G42/2) -> 0.022956422 | I24: ='P & L Statement'!H21/('Balance Sheet'!G42+'Balance Sheet'!H42/2) -> 0.024727603
A25: 19 | B25: Return On Equity | C25: ='P & L Statement'!B23/'Balance Sheet'!B7/2 -> 0.048753614 | D25: ='P & L Statement'!C23/('Balance Sheet'!B7+'Balance Sheet'!C7/2) -> 0.30229808 | E25: ='P & L Statement'!D23/('Balance Sheet'!C7+'Balance Sheet'!D7/2) -> 0.050259516 | F25: ='P & L Statement'!E23/('Balance Sheet'!D7+'Balance Sheet'!E7/2) -> -0.02937264 | G25: ='P & L Statement'!F23/('Balance Sheet'!E7+'Balance Sheet'!F7/2) -> 0.023468148 | H25: ='P & L Statement'!G23/('Balance Sheet'!F7+'Balance Sheet'!G7/2) -> 0.10389754 | I25: ='P & L Statement'!H23/('Balance Sheet'!G7+'Balance Sheet'!H7/2) -> 0.097537527
A26: 20 | B26: Return on Capital Employed | C26: =('P & L Statement'!B15-'P & L Statement'!B18)/('Balance Sheet'!B42-'Balance Sheet'!B20) -> 0.077632876 | D26: =('P & L Statement'!C15-'P & L Statement'!C18)/('Balance Sheet'!C42-'Balance Sheet'!C20) -> 0.28434251 | E26: =('P & L Statement'!D15-'P & L Statement'!D18)/('Balance Sheet'!D42-'Balance Sheet'!D20) -> 0.074106597 | F26: =('P & L Statement'!E15-'P & L Statement'!E18)/('Balance Sheet'!E42-'Balance Sheet'!E20) -> 0.0099813724 | G26: =('P & L Statement'!F15-'P & L Statement'!F18)/('Balance Sheet'!F42-'Balance Sheet'!F20) -> 0.08025049 | H26: =('P & L Statement'!G15-'P & L Statement'!G18)/('Balance Sheet'!G42-'Balance Sheet'!G20) -> 0.10375088 | I26: =('P & L Statement'!H15-'P & L Statement'!H18)/('Balance Sheet'!H42-'Balance Sheet'!H20) -> 0.10712121
